<?xml version="1.0" encoding="utf-8"?>
<robot name="dvrk_psm" xmlns:xacro="http://www.ros.org/wiki/xacro">

  <xacro:macro name="psm" params="prefix parent_link xyz rpy">
    <!-- fixed joint -->
    <joint name="${prefix}fixed_joint" type="fixed">
      <parent link="${parent_link}"/>
      <child link="${prefix}remote_center_link"/>
      <origin rpy="${rpy}" xyz="${xyz}"/>
    </joint>

    <!-- link rc: remote centre link -->
    <link name="${prefix}remote_center_link" />   

    <!-- fixed joint -->
    <joint name="${prefix}rc_fixed_joint" type="fixed">
      <parent link="${prefix}remote_center_link"/>
      <child link="${prefix}psm_base_link"/>
      <origin rpy="0 0 0" xyz="0 -0.369 0"/>
    </joint>

    <!-- link 0: psm base link -->
    <link name="${prefix}psm_base_link">
    <inertial>
      <mass value="0.01"/>
      <origin rpy="1.5708 0 3.1416" xyz="0.039 -0.03888 -0.07879"/>
      <inertia ixx="1.0" ixy="0.0" ixz="0.0" iyy="1.0" iyz="0.0" izz="1.0"/>
    </inertial>
      
      <visual>
        <origin rpy="1.5708 0 3.1416" xyz="0.039 -0.03888 -0.07879"/>
        <geometry>
          <mesh filename="package://dvrk_model/meshes/psm/psm_base.dae"/>      
        </geometry>
      </visual>
	<collision>
        <origin rpy="1.5708 0 3.1416" xyz="0.039 -0.03888 -0.07879"/>
        <geometry>
          <mesh filename="package://dvrk_model/meshes/psm/psm_base.dae"/>      
        </geometry>
      </collision>

    </link>
    
    <!-- joint 1 -->
    <joint name="${prefix}outer_yaw_joint" type="revolute">
      <parent link="${prefix}psm_base_link"/>
      <child link="${prefix}outer_yaw_link"/>
      <axis xyz="0 0 1"/>
      <origin rpy="1.5708 -1.5708 0" xyz="0.0 0.0 0.0"/>
      <limit lower="-1.5707" upper="1.5707" velocity=".4" effort="1000"/>
    </joint> 
    
    
    <!-- link 1: outer_yaw -->
    <link name="${prefix}outer_yaw_link">

    <inertial>
      <mass value="0.01"/>
      <origin rpy="3.1416 0 1.5708" xyz="0.0125 0 0.1575"/>
      <inertia ixx="1.0" ixy="0.0" ixz="0.0" iyy="1.0" iyz="0.0" izz="1.0"/>
    </inertial>

      <visual>
        <!-- <origin rpy="0 0 -1.5708" xyz="0.0125 0 0.1575"/> -->
        <origin rpy="3.1416 0 1.5708" xyz="0.0125 0 0.1575"/>
        <geometry>
          <mesh filename="package://dvrk_model/meshes/psm/outer_yaw.dae"/>      
        </geometry>
      </visual>
      <collision>
        <!-- <origin rpy="0 0 -1.5708" xyz="0.0125 0 0.1575"/> -->
        <origin rpy="3.1416 0 1.5708" xyz="0.0125 0 0.1575"/>
        <geometry>
          <mesh filename="package://dvrk_model/meshes/psm/outer_yaw.dae"/>      
        </geometry>
      </collision>
    </link>

    <!-- link 2: outer_pitch_back -->
    <link name="${prefix}outer_pitch_back_link">

    <inertial>
      <mass value="0.01"/>
      <origin rpy="0 0 -0.27129" xyz="0 0 0"/>
      <inertia ixx="1.0" ixy="0.0" ixz="0.0" iyy="1.0" iyz="0.0" izz="1.0"/>
    </inertial>
      <visual>
        <origin rpy="0 0 -0.27129" xyz="0 0 0"/>
        <geometry>
          <mesh filename="package://dvrk_model/meshes/psm/outer_pitch_back.dae"/>      
        </geometry>
      </visual>
    <collision>
        <origin rpy="0 0 -0.27129" xyz="0 0 0"/>
        <geometry>
          <mesh filename="package://dvrk_model/meshes/psm/outer_pitch_back.dae"/>      
        </geometry>
      </collision>
    </link>

    <!-- link 2-2: outer_pitch_front -->
    <link name="${prefix}outer_pitch_front_link">

    <inertial>
      <mass value="0.01"/>
      <origin rpy="0 0 -0.27129" xyz="0 0 0"/>
      <inertia ixx="1.0" ixy="0.0" ixz="0.0" iyy="1.0" iyz="0.0" izz="1.0"/>
    </inertial>

     <!-- <visual>
        <origin rpy="0 0 -0.27129" xyz="0 0 0"/>-->
        <!-- <origin rpy="0 0 0" xyz="0 0 0"/> -->
       <!-- <geometry>
          <mesh filename="package://dvrk_model/meshes/psm/outer_pitch_front.dae"/>      
        </geometry>
      </visual>-->
     <collision>
        <origin rpy="0 0 -0.27129" xyz="0 0 0"/>
        <!-- <origin rpy="0 0 0" xyz="0 0 0"/> -->
        <geometry>
          <mesh filename="package://dvrk_model/meshes/psm/outer_pitch_front.dae"/>      
        </geometry>
      </collision>
    </link>

    <!-- link 2-3: outer_pitch_bottom -->
    <link name="${prefix}outer_pitch_bottom_link">

      <inertial>
      	<mass value="0.01"/>
      	<origin rpy="0 -1.5708 0" xyz="0.009 0 0"/>
      	<inertia ixx="1.0" ixy="0.0" ixz="0.0" iyy="1.0" iyz="0.0" izz="1.0"/>
      </inertial>
      <visual>
        <origin rpy="0 -1.5708 0" xyz="0.009 0 0"/>
        <geometry>
          <mesh filename="package://dvrk_model/meshes/psm/outer_pitch_bottom.dae"/>      
        </geometry>
      </visual>
      <collision>
        <origin rpy="0 -1.5708 0" xyz="0.009 0 0"/>
        <geometry>
          <mesh filename="package://dvrk_model/meshes/psm/outer_pitch_bottom.dae"/>      
        </geometry>
      </collision>
    </link>

    <!-- link 2-4: outer_pitch_top -->
    <link name="${prefix}outer_pitch_top_link">

      <inertial>
      	<mass value="0.01"/>
      	<origin rpy="0 -1.5708 0" xyz="0.009 0 0"/>
      	<inertia ixx="1.0" ixy="0.0" ixz="0.0" iyy="1.0" iyz="0.0" izz="1.0"/>
      </inertial>
      <visual>
        <origin rpy="0 -1.5708 0" xyz="0.009 0 0"/>
        <geometry>
          <mesh filename="package://dvrk_model/meshes/psm/outer_pitch_top.dae"/>      
        </geometry>
      </visual>
      <collision>
        <origin rpy="0 -1.5708 0" xyz="0.009 0 0"/>
        <geometry>
          <mesh filename="package://dvrk_model/meshes/psm/outer_pitch_top.dae"/>      
        </geometry>
      </collision>
    </link>

    <!-- link 2-5: outer_insertion -->
    <link name="${prefix}outer_insertion_link">
      <inertial>
      	<mass value="0.01"/>
      	<origin rpy="0 -1.5708 1.5708" xyz="0.02528 0.429 0"/>
      	<inertia ixx="1.0" ixy="0.0" ixz="0.0" iyy="1.0" iyz="0.0" izz="1.0"/>
      </inertial>
      <visual>
        <origin rpy="0 -1.5708 1.5708" xyz="0.02528 0.429 0"/>
        <geometry>
          <mesh filename="package://dvrk_model/meshes/psm/outer_insertion.dae"/>      
        </geometry>
      </visual>
      <collision>
        <origin rpy="0 -1.5708 1.5708" xyz="0.02528 0.429 0"/>
        <geometry>
          <mesh filename="package://dvrk_model/meshes/psm/outer_insertion.dae"/>      
        </geometry>
      </collision>

    </link>

    <!-- joint 2-1: outer_pitch_1 -->
<gazebo>
    <joint name="${prefix}outer_pitch_joint_1" type="revolute">
      <parent link="${prefix}outer_yaw_link"/>
      <child link="${prefix}outer_pitch_back_link"/>
      <axis xyz="0 0 1"/>
      <origin rpy="-1.5708 -1.5708 0" xyz="0 0.0295 0.1495"/>
      <!--<limit lower="-0.7854" upper="0.7854" velocity=".4" effort="1000"/>-->
      <limit lower="-1.5708" upper="1.5708" velocity=".4" effort="1000"/>	
    </joint> 
</gazebo>    
    <!-- joint 2-2: outer_pitch_2 -->
<gazebo>
    <joint name="${prefix}outer_pitch_joint_2" type="continuous">
      <parent link="${prefix}outer_yaw_link"/>
      <child link="${prefix}outer_pitch_front_link"/>
      <axis xyz="0 0 1"/>
      <origin rpy="-1.5708 -1.5708 0" xyz="0 0.0295 0.0595"/>
      <mimic joint="${prefix}outer_pitch_joint_1" multiplier="1"/>
    </joint>
</gazebo>

    <!-- joint 2-3: outer_pitch_3 -->
<gazebo>
    <joint name="${prefix}outer_pitch_joint_3" type="continuous">
      <parent link="${prefix}outer_pitch_back_link"/>
      <child link="${prefix}outer_pitch_bottom_link"/>
      <axis xyz="0 0 1"/>
      <origin rpy="0 0 0" xyz="0.04178 0.15007 -0.0137"/>
      <mimic joint="${prefix}outer_pitch_joint_1" multiplier="-1"/>
    </joint>
</gazebo>

    <!-- joint 2-4: outer_pitch_4 -->
<gazebo>
    <joint name="${prefix}outer_pitch_joint_4" type="continuous">
      <parent link="${prefix}outer_pitch_bottom_link"/>
      <child link="${prefix}outer_pitch_front_link"/>
      <axis xyz="0 0 1"/>
      <origin rpy="0 0 0" xyz="0.04209 0.18695 -0.02412"/>
      <mimic joint="${prefix}outer_pitch_joint_1" multiplier="-1"/>
    </joint>
</gazebo>

    <!-- joint 2-5: outer_pitch_5 -->
    <joint name="${prefix}outer_pitch_joint_5" type="continuous">
      <parent link="${prefix}outer_pitch_back_link"/>
      <child link="${prefix}outer_pitch_top_link"/>
      <axis xyz="0 0 1"/>
      <origin rpy="0 0 0" xyz="-0.520 0 -0.0155"/>
      <mimic joint="${prefix}outer_pitch_joint_1" multiplier="1"/>
    </joint>


    <!-- joint 3: insertion -->
    <joint name="${prefix}outer_insertion_joint" type="prismatic">
      <parent link="${prefix}outer_insertion_link"/>
      <child link="${prefix}tool_main_link"/>
      <axis xyz="0 0 1"/>
      <origin rpy="1.5708 0 0" xyz="-0.0403 0.23622 0"/>
      <limit lower="0" upper="0.240" velocity=".4" effort="1000"/>
    </joint>

    <!-- link 3: tool_main_link -->
    <link name="${prefix}tool_main_link">

      <inertial>
      	<mass value="0.01"/>
      	<origin rpy="0 0 1.5708" xyz="0 0 0"/>
      	<inertia ixx="1.0" ixy="0.0" ixz="0.0" iyy="1.0" iyz="0.0" izz="1.0"/>
      </inertial>
      <visual>
        <origin rpy="0 0 1.5708" xyz="0 0 0"/>
        <geometry>
          <mesh filename="package://dvrk_model/meshes/psm/tool_main.dae"/>      
        </geometry>
      </visual>
  <collision>
        <origin rpy="0 0 1.5708" xyz="0 0 0"/>
        <geometry>
          <mesh filename="package://dvrk_model/meshes/psm/tool_main.dae"/>      
        </geometry>
      </collision>
    </link>
  </xacro:macro> 
</robot>
